Traceback (most recent call last):
  File "/glade/u/home/mollyw/.conda/envs/cice-scm-da/lib/python3.11/site-packages/xarray/backends/file_manager.py", line 211, in _acquire_with_cache_info
    file = self._cache[self._key]
           ~~~~~~~~~~~^^^^^^^^^^^
  File "/glade/u/home/mollyw/.conda/envs/cice-scm-da/lib/python3.11/site-packages/xarray/backends/lru_cache.py", line 56, in __getitem__
    value = self._cache[key]
            ~~~~~~~~~~~^^^^^
KeyError: [<class 'netCDF4._netCDF4.Dataset'>, ('/glade/work/mollyw/Projects/cice_scm_da/data/forcings/ICE_PERTS/parameters_30_cice5.nc',), 'r', (('clobber', True), ('diskless', False), ('format', 'NETCDF4'), ('persist', False)), '47f75f74-a8ea-4072-9a4a-6f06f9a5292b']

During handling of the above exception, another exception occurred:

Traceback (most recent call last):
  File "/glade/work/mollyw/Projects/cice-scm-da/cice_scm_da/ensemble/01_spinup_ensemble.py", line 83, in <module>
    parameters = xr.open_dataset(project_dir+ '/data/forcings/ICE_PERTS/parameters_30_cice5.nc')
                 ^^^^^^^^^^^^^^^^^^^^^^^^^^^^^^^^^^^^^^^^^^^^^^^^^^^^^^^^^^^^^^^^^^^^^^^^^^^^^^^
  File "/glade/u/home/mollyw/.conda/envs/cice-scm-da/lib/python3.11/site-packages/xarray/backends/api.py", line 566, in open_dataset
    backend_ds = backend.open_dataset(
                 ^^^^^^^^^^^^^^^^^^^^^
  File "/glade/u/home/mollyw/.conda/envs/cice-scm-da/lib/python3.11/site-packages/xarray/backends/netCDF4_.py", line 590, in open_dataset
    store = NetCDF4DataStore.open(
            ^^^^^^^^^^^^^^^^^^^^^^
  File "/glade/u/home/mollyw/.conda/envs/cice-scm-da/lib/python3.11/site-packages/xarray/backends/netCDF4_.py", line 391, in open
    return cls(manager, group=group, mode=mode, lock=lock, autoclose=autoclose)
           ^^^^^^^^^^^^^^^^^^^^^^^^^^^^^^^^^^^^^^^^^^^^^^^^^^^^^^^^^^^^^^^^^^^^
  File "/glade/u/home/mollyw/.conda/envs/cice-scm-da/lib/python3.11/site-packages/xarray/backends/netCDF4_.py", line 338, in __init__
    self.format = self.ds.data_model
                  ^^^^^^^
  File "/glade/u/home/mollyw/.conda/envs/cice-scm-da/lib/python3.11/site-packages/xarray/backends/netCDF4_.py", line 400, in ds
    return self._acquire()
           ^^^^^^^^^^^^^^^
  File "/glade/u/home/mollyw/.conda/envs/cice-scm-da/lib/python3.11/site-packages/xarray/backends/netCDF4_.py", line 394, in _acquire
    with self._manager.acquire_context(needs_lock) as root:
  File "/glade/u/home/mollyw/.conda/envs/cice-scm-da/lib/python3.11/contextlib.py", line 137, in __enter__
    return next(self.gen)
           ^^^^^^^^^^^^^^
  File "/glade/u/home/mollyw/.conda/envs/cice-scm-da/lib/python3.11/site-packages/xarray/backends/file_manager.py", line 199, in acquire_context
    file, cached = self._acquire_with_cache_info(needs_lock)
                   ^^^^^^^^^^^^^^^^^^^^^^^^^^^^^^^^^^^^^^^^^
  File "/glade/u/home/mollyw/.conda/envs/cice-scm-da/lib/python3.11/site-packages/xarray/backends/file_manager.py", line 217, in _acquire_with_cache_info
    file = self._opener(*self._args, **kwargs)
           ^^^^^^^^^^^^^^^^^^^^^^^^^^^^^^^^^^^
  File "src/netCDF4/_netCDF4.pyx", line 2464, in netCDF4._netCDF4.Dataset.__init__
  File "src/netCDF4/_netCDF4.pyx", line 2027, in netCDF4._netCDF4._ensure_nc_success
FileNotFoundError: [Errno 2] No such file or directory: '/glade/work/mollyw/Projects/cice_scm_da/data/forcings/ICE_PERTS/parameters_30_cice5.nc'
